<?xml version="1.0"?>

<robot name="wheel" xmlns:xacro="http://www.ros.org/wiki/xacro">

    <xacro:property name="PI" value="3.1415926535897931" />
    <xacro:property name="wheel_radius" value="0.127" />
    <xacro:property name="wheel_height" value="0.096" />
    <xacro:property name="wheel_mass" value="6.5" />

    <xacro:macro name="cylinder_iteria" params="m r h">
        <inertia  ixx="${m*(3*r*r+h*h)/12}" ixy = "0" ixz = "0"
              iyy="${m*r*r/2}" iyz = "0"
              izz="${m*(3*r*r+h*h)/12}" />       
    </xacro:macro>

    <xacro:macro name="toan_wheel" params="prefix parent *origin reflect">

        <link name="${prefix}_wheel_link">
            <visual>
                <origin xyz="0.0 0.0 0.0" rpy="0.0 0.0 0.0" />
                <xacro:if value="${reflect}">
                    <geometry>
                        <mesh filename="package://robot_model/meshes/wheels/omni_wheel_1.dae" />
                    </geometry>
                </xacro:if>
                <xacro:unless value="${reflect}">
                    <geometry>
                         <mesh filename="package://robot_model/meshes/wheels/omni_wheel_2.dae" />
                    </geometry>
		        </xacro:unless>
            </visual>

            <collision>
				<origin xyz="0 0 0" rpy="${PI/2} 0 0" />
                <geometry>
					<cylinder length="${wheel_height}" radius="${wheel_radius}" />
                </geometry>
            </collision>

            <inertial>
                <mass value="${wheel_mass}" />
                <origin xyz="0 0 0" />
                <cylinder_iteria  m="${wheel_mass}" r="${wheel_radius}" h="${wheel_height}" />
            </inertial>

        </link>

        <joint name="${prefix}_wheel_joint" type="continuous">
            <parent link="${parent}"/>
            <child link="${prefix}_wheel_link"/>
            <xacro:insert_block name="origin" />
            <axis xyz="0 1 0" rpy="0 0 0" />
            <limit effort="100" velocity="100"/>
            <joint_properties damping="1.0" friction="1.0"/>
        </joint>

    
     
    </xacro:macro>


</robot>